Workbook

Sheet SOA-TSL Payable
A2: Statement of Accounts (SOA)
A3: Tata Bluescope (TBSL)
A5: TSL Payable - TBSL Receivable
A7: Sl.No | B7: Particulars | C7: As per Tata Steel (Rs.) | D7: As per TBSL (Rs.) | E7: Difference
A8: 1 | B8: Opening Balance as on 01.04.2019 | C8: 46541723 | D8: 50979645 | E8: =C8-D8 -> -4437921.9
A9: 2a. | B9: Transactions | C9: =-C20 -> 2.3083245e+08 | D9: =C26 -> 2.2011657e+08 | E9: =C9-D9 -> 10715876
A10: 2b. | B10: GST | C10: =-TSL!Q671 -> 34636394 | D10: =TBSL!Q1494 -> 39671816 | E10: =C10-D10 -> -5035421.6 | F10: Take Totals of GST column by filtering via same dcument type as in Txn
A11: 2 | B11: Total Transaction | C11: =SUM(C9:C10) -> 2.6546884e+08 | D11: =SUM(D9:D10) -> 2.5978839e+08 | E11: =C11-D11 -> 5680454
A12: 3 | B12: Total Payments/Collection | C12: =C13-C11-C8 -> -2.5124551e+08 | D12: =D13-D11-D8 -> -2.3460043e+08 | E12: =C12-D12 -> -16645082
A13: 4 | B13: Closing Balance as on 31.03.2020 | C13: 60765053 | D13: 76167603 | E13: =C13-D13 -> -15402550
B17: provision | C17: -3562266.1
B18: GRIR | C18: -36247052
B19: Transaction | C19: =TSL!L671 -> -1.9102313e+08 | D19: (RE,RL,RA, SA, SB Summ) | E19: (Amt in Loc Curr – GST amt+wTA) | F19: amt in loc cur + wTA = (2)(Total Txn)
B20: Tata steel total transaction | C20: =SUM(C17:C19) -> -2.3083245e+08
B25: Transaction | C25: =TBSL!L1493 -> 2.2011657e+08 | D25: (only RV) | E25: (Amt in Loc Curr – GST amt+wTA)
B26: TBSL total transaction | C26: =SUM(C25:C25) -> 2.2011657e+08
C38: 72978936
C39: -81433170

Sheet Form 2 TSL Payable
A1: TATA STEEL LIMITED - CONSOLIDATED FINANCIAL STATEMENTS | E1: Form - 2
A3: Details of transactions and balances
A5: Category : Subsidiary
A7: Name of the Company : Tata Bluescope (TBSL) | E7: (From the stand point of Tata Steel)
A8: Period : April 2019 to March 2020
A9: Nature of transactions | B9: Balance as per TSL | C9: Balance as per RP | D9: Difference | E9: Remarks (*)
A11: Purchases of Goods | B11: ='SOA-TSL Payable'!C9 -> 2.3083245e+08
A12: Sale of Goods | C12: ='SOA-TSL Payable'!D9 -> 2.2011657e+08
A13: Purchase of Fixed Assets
A14: Sale of Fixed Assets
A15: Purchase of Investments
A16: Sale of Investments
A17: Rendering of Services | D17: =B11-C12 -> 10715876 | E17: See Transaction reco
A18: Receiving of Services
A19: Agency arrangements (income)
A20: Leasing or hire purchase arrangements
A21: Finance provided(including loans and equity contributions in cash or in kind)
A22: Interest income during the year
A23: Finance received (including loans and equity contributions in cash or in kind)
A24: Interest paid during the year
A25: Guarantees and collaterals given
A26: Contributions made to employee benefit trusts
A27: Management Contracts including deputation of employees
A28: Dividend income
A29: Provision for receivables made during the year
... A37: Debit balances outstanding as on 31.03.2020
A38: Outstanding receivables- Debtors | C38: =Balances!C6 -> 76387905
A39: Outstanding receivables- Advance
A43: Credit balances outstanding as on 31.03.2020
A44: Outstanding payables- Creditors | B44: ='SOA-TSL Payable'!C13 -> 60765053 | D44: =B44-(C38-C45) -> -15402550 | E44: See BL Reco
A45: Outstanding payables- Advance | C45: =-Balances!C5 -> 220301.86
A47: Provision for outstanding receivables
A49: * If any figure does not agree and there are differences then the reconciliation must accompany the statement. However, reconciliation
A50: item should not be a result of any items which should have been recognised and accounted for by Tata Steel.
A55: Note :
A56: 1. The location must have full transaction level / financial code level back up for each of the figures given below.
A57: 2. If there are no transaction with any of the companies referred to in Annexure 1, then a NIL certificate should be enclosed.

Sheet Transaction reco-TSL Pay
B2: Transaction Reconciliation for the period 01.04.2019 to 31.03.2020 - TSL Payable TBSL Receivable
B3: Particulars | C3: Balance as on 31.03.2020 | D3: Balance as on 31.03.2019 | E3: Transaction reco for the period
B4: As per RP | E4: ='SOA-TSL Payable'!C26 -> 2.2011657e+08
B6: Reasons for Differences (Add/Less):
B7: Invoice diff in GRIR booked with GST | E7: =D7-C7 -> 0
B8: Material in Transit | C8: =MIT!N13 -> 7737321.6 | E8: =D8-C8 -> -7737321.6
B9: Transaction of last year | C9: ='Last year Items'!K68 -> -21471051 | E9: =D9-C9 -> 21471051
B10: Short provision by TSL | C10: ='Short provi'!O27 -> 3104833 | E10: =D10-C10 -> -3104833
B11: Invoice Difference | C11: ='Invoice Diff'!L159 -> 188485.18 | E11: =D11-C11 -> -188485.18
B12: Invoice Difference in GRIR | C12: ='Invoice diff in GRIR'!L24 -> 15159.63 | E12: =D12-C12 -> -15159.63
B13: Under reco | C13: -290623.58 | E13: =D13-C13 -> 290623.58
B15: Balance after above adjustments | C15: =SUM(C6:C11) -> -10440412 | E15: =SUM(E4:E13) -> 2.3083245e+08
B16: As per Tata Steel Ltd | E16: ='SOA-TSL Payable'!C20*-1 -> 2.3083245e+08
B17: Difference | E17: =E15-E16 -> 0
C38: 72978936
C39: -81433170

Sheet TSL
A1: Company_Code | B1: Company_Name | C1: SAP_Doc_Number | D1: Reference | E1: Document_Type | F1: Business_Area | G1: Fiscal_Year | H1: Posting_Period | I1: Doc/Chq_Date | J1: Posting_Date | K1: Amount_in_Local_Currency | L1: SOA | M1: Local_Currency | N1: Amount_in_Document_Currency | O1: Document_Currency | P1: Discount_Base_Amount | Q1: GST_Amount | R1: Net_Amount | S1: Withholding_Tax_Base_Amount | T1: Withholding_Tax_Amount | U1: Vendor/Customer | V1: Vendor/Customer_Name | W1: Trading_Partner | X1: Text | Y1: HDR_Text | Z1: Inv/SO_Reference | AA1: Plant | AB1: Purchasing_Document | AC1: Delivery_Note | AD1: Account | AE1: Account_Description | AF1: Offsetting_Account | AG1: Offsetting_Acct_Name | AH1: GRIR_Offsetting_Account | AI1: Final_Offsetting_Account | AJ1: Final_Offsetting_Acct_Name | AK1: WBS_Element | AL1: Posting_Key | AM1: Debit/Credit | AN1: Special_G/L_Ind. | AO1: Reversal_Indicator | AP1: Clearing_Doc | AQ1: Clearing_Date | AR1: Entry_date | AS1: Entry_Time | AT1: Notional_GST | AU1: Gross_Amount_In_Local_Currency | AV1: DE_Indicator | AW1: PO_Line | AX1: Entry_Line
A2: 1000 | B2: Tata Steel Limited | C2: 42009213 | D2: DD NO-007452, | E2: KG | F2: 9500 | G2: 2020 | H2: 3 | I2: 43640 | J2: 43640 | K2: 2000 | L2: =K2-Q2+T2 -> 1694.91 | M2: INR | N2: 2000 | O2: INR | P2: 2000 | Q2: 305.09 | R2: 1694.91 | S2: 0 | T2: 0 | U2: T040 | V2: TATA BLUESCOPE STEEL PRIVATE LIMIT | X2: Gate pass penalty, DD no -007452, IDBI | Y2: gatepass penalty | Z2: 42009213 | AD2: 2408402 | AE2: Vendor Reconciliation Account - Domestic | AF2: 3263001 | AG2: Miscellaneous Income Jsr | AI2: 3263001 | AJ2: Miscellaneous Income Jsr | AK2: 0 | AL2: 21 | AM2: S | AP2: 91510334 | AQ2: 24-06-2019 | AR2: 24-06-2019 | AS2: 16:52:22 | AT2: 0 | AU2: 2000 | AX2: 1
A3: 1000 | B3: Tata Steel Limited | C3: 42034968 | D3: GST/TSK/DN/235 | E3: KG | F3: 9600 | G3: 2020 | H3: 5 | I3: 43678 | J3: 43700 | K3: 8673 | L3: =K3-Q3+T3 -> 7350 | M3: INR | N3: 8673 | O3: INR | P3: 8673 | Q3: 1323 | R3: 7350 | S3: 0 | T3: 0 | U3: T040 | V3: TATA BLUESCOPE STEEL PRIVATE LIMIT | X3: Hiring of Equipments | Y3: 3800014331 | Z3: 42034968 | AD3: 2408402 | AE3: Vendor Reconciliation Account - Domestic | AF3: 3263001 | AG3: Miscellaneous Income Jsr | AI3: 3263001 | AJ3: Miscellaneous Income Jsr | AK3: 0 | AL3: 21 | AM3: S | AR3: 23-08-2019 | AS3: 12:43:29 | AT3: 0 | AU3: 8673 | AX3: 1
A4: 1000 | B4: Tata Steel Limited | C4: 42035904 | D4: DD NO -007588 | E4: KG | F4: 9500 | G4: 2020 | H4: 6 | I4: 43719 | J4: 43719 | K4: 800 | L4: =K4-Q4+T4 -> 677.97 | M4: INR | N4: 800 | O4: INR | P4: 800 | Q4: 122.03 | R4: 677.97 | S4: 0 | T4: 0 | U4: T040 | V4: TATA BLUESCOPE STEEL PRIVATE LIMIT | X4: Gate pass penaty , T040 | Y4: Gate pass Penalty | Z4: 42035904 | AD4: 2408402 | AE4: Vendor Reconciliation Account - Domestic | AF4: 3265003 | AG4: MISCELLANEOUS INCOME | AI4: 3265003 | AJ4: MISCELLANEOUS INCOME | AK4: 0 | AL4: 21 | AM4: S | AP4: 92076426 | AQ4: 11-09-2019 | AR4: 11-09-2019 | AS4: 12:53:10 | AT4: 0 | AU4: 800 | AX4: 1
A5: 1000 | B5: Tata Steel Limited | C5: 42035915 | D5: DD 007588 | E5: KG | F5: 9500 | G5: 2020 | H5: 6 | I5: 43719 | J5: 43720 | K5: 800 | L5: =K5-Q5+T5 -> 677.97 | M5: INR | N5: 800 | O5: INR | P5: 800 | Q5: 122.03 | R5: 677.97 | S5: 0 | T5: 0 | U5: T040 | V5: TATA BLUESCOPE STEEL PRIVATE LIMIT | X5: DOC TO DELETE | Y5: Gatepass penalty | Z5: 42035915 | AD5: 2408402 | AE5: Vendor Reconciliation Account - Domestic | AF5: 3265003 | AG5: MISCELLANEOUS INCOME | AI5: 3265003 | AJ5: MISCELLANEOUS INCOME | AK5: 0 | AL5: 21 | AM5: S | AR5: 12-09-2019 | AS5: 09:21:32 | AT5: 0 | AU5: 800 | AX5: 1
A6: 1000 | B6: Tata Steel Limited | C6: 42041185 | D6: GATEPASS/RFID | E6: KG | F6: 9600 | G6: 2020 | H6: 10 | I6: 43860 | J6: 43860 | K6: 1100 | L6: =K6-Q6+T6 -> 932.2 | M6: INR | N6: 1100 | O6: INR | P6: 1100 | Q6: 167.8 | R6: 932.2 | S6: 0 | T6: 0 | U6: T018 | V6: TATA BLUESCOPE STEEL PRIVATE LIMIT | X6: Gatepass/RFID Recovery from Vendor | Y6: Gatepas Penalty | Z6: 42041185 | AD6: 2408402 | AE6: Vendor Reconciliation Account - Domestic | AF6: 3265003 | AG6: MISCELLANEOUS INCOME | AI6: 3265003 | AJ6: MISCELLANEOUS INCOME | AK6: 0 | AL6: 21 | AM6: S | AP6: 92978106 | AQ6: 30-01-2020 | AR6: 30-01-2020 | AS6: 09:15:37 | AT6: 0 | AU6: 1100 | AX6: 1
A7: 1000 | B7: Tata Steel Limited | C7: 42041545 | D7: DD NO-186797 | E7: KG | F7: 9500 | G7: 2020 | H7: 11 | I7: 43868 | J7: 43868 | K7: 400 | L7: =K7-Q7+T7 -> 338.98 | M7: INR | N7: 400 | O7: INR | P7: 400 | Q7: 61.02 | R7: 338.98 | S7: 0 | T7: 0 | U7: T040 | V7: TATA BLUESCOPE STEEL PRIVATE LIMIT | X7: UNION BANK DT 07.02.2019 | Y7: Gate pass Penalty | Z7: 42041545 | AD7: 2408402 | AE7: Vendor Reconciliation Account - Domestic | AF7: 3265003 | AG7: MISCELLANEOUS INCOME | AI7: 3265003 | AJ7: MISCELLANEOUS INCOME | AK7: 0 | AL7: 21 | AM7: S | AP7: 93046164 | AQ7: 07-02-2020 | AR7: 07-02-2020 | AS7: 15:46:49 | AT7: 0 | AU7: 400 | AX7: 1
A8: 1000 | B8: Tata Steel Limited | C8: 42041546 | D8: DD NO-186798 | E8: KG | F8: 9500 | G8: 2020 | H8: 11 | I8: 43868 | J8: 43868 | K8: 200 | L8: =K8-Q8+T8 -> 169.49 | M8: INR | N8: 200 | O8: INR | P8: 200 | Q8: 30.51 | R8: 169.49 | S8: 0 | T8: 0 | U8: T040 | V8: TATA BLUESCOPE STEEL PRIVATE LIMIT | X8: UNION BANK DT 07.02.2019 | Y8: Gate pass Penalty | Z8: 42041546 | AD8: 2408402 | AE8: Vendor Reconciliation Account - Domestic | AF8: 3265003 | AG8: MISCELLANEOUS INCOME | AI8: 3265003 | AJ8: MISCELLANEOUS INCOME | AK8: 0 | AL8: 21 | AM8: S | AP8: 93046166 | AQ8: 07-02-2020 | AR8: 07-02-2020 | AS8: 15:49:59 | AT8: 0 | AU8: 200 | AX8: 1
A9: 1000 | B9: Tata Steel Limited | C9: 44234301 | D9: TDS ON PROVISION | E9: KR | F9: 9000 | G9: 2020 | H9: 12 | I9: 31-03-2020 | J9: 31-03-2020 | K9: 26922 | L9: =K9-Q9+T9 -> 26922 | M9: INR | N9: 26922 | O9: INR | P9: 0 | Q9: 0 | R9: 26922 | S9: 0 | T9: 0 | U9: T018 | V9: TATA BLUESCOPE STEEL PRIVATE LIMIT | X9: TDS on Year End Manual Prov FY 2020 | Y9: TDS on Provisions Manual | Z9: V | AD9: 2408402 | AE9: Vendor Reconciliation Account - Domestic | AF9: T018 | AG9: TATA BLUESCOPE STEEL PRIVATE LIMIT | AI9: 2408402 | AJ9: Vendor Reconciliation Account - Domestic | AK9: 0 | AL9: 21 | AM9: S | AR9: 07-04-2020 | AS9: 16:14:04 | AT9: 0 | AU9: 26922 | AX9: 2
A10: 1000 | B10: Tata Steel Limited | C10: 44234301 | D10: TDS ON PROVISION | E10: KR | F10: 9000 | G10: 2020 | H10: 12 | I10: 31-03-2020 | J10: 31-03-2020 | K10: -26922 | L10: =K10-Q10+T10 -> -26922 | M10: INR | N10: -26922 | O10: INR | P10: 0 | Q10: 0 | R10: -26922 | S10: 0 | T10: 0 | U10: T018 | V10: TATA BLUESCOPE STEEL PRIVATE LIMIT | X10: TDS on Year End Manual Prov FY 2020 | Y10: TDS on Provisions Manual | Z10: 44234301 | AD10: 2408402 | AE10: Vendor Reconciliation Account - Domestic | AF10: 2405215 | AG10: Provisional Liability for TDS on Povision- Manual | AI10: 2405215 | AJ10: Provisional Liability for TDS on Povision- Manual | AK10: 0 | AL10: 31 | AM10: H | AR10: 07-04-2020 | AS10: 16:14:04 | AT10: 0 | AU10: -26922 | AX10: 3
A11: 1000 | B11: Tata Steel Limited | C11: 44234302 | D11: TDS ON PROVISION | E11: KR | F11: 9000 | G11: 2020 | H11: 12 | I11: 31-03-2020 | J11: 31-03-2020 | K11: -64706 | L11: =K11-Q11+T11 -> -64706 | M11: INR | N11: -64706 | O11: INR | P11: 0 | Q11: 0 | R11: -64706 | S11: 0 | T11: 0 | U11: T018 | V11: TATA BLUESCOPE STEEL PRIVATE LIMIT | X11: TDS on Year End Manual Prov FY 2020 | Y11: TDS on Provisions Manual | Z11: 44234302 | AD11: 2408402 | AE11: Vendor Reconciliation Account - Domestic | AF11: 2405215 | AG11: Provisional Liability for TDS on Povision- Manual | AI11: 2405215 | AJ11: Provisional Liability for TDS on Povision- Manual | AK11: 0 | AL11: 31 | AM11: H | AR11: 07-04-2020 | AS11: 16:14:06 | AT11: 0 | AU11: -64706 | AX11: 3
A12: 1000 | B12: Tata Steel Limited | C12: 44234302 | D12: TDS ON PROVISION | E12: KR | F12: 9000 | G12: 2020 | H12: 12 | I12: 31-03-2020 | J12: 31-03-2020 | K12: 64706 | L12: =K12-Q12+T12 -> 64706 | M12: INR | N12: 64706 | O12: INR | P12: 0 | Q12: 0 | R12: 64706 | S12: 0 | T12: 0 | U12: T018 | V12: TATA BLUESCOPE STEEL PRIVATE LIMIT | X12: TDS on Year End Manual Prov FY 2020 | Y12: TDS on Provisions Manual | Z12: V | AD12: 2408402 | AE12: Vendor Reconciliation Account - Domestic | AF12: T018 | AG12: TATA BLUESCOPE STEEL PRIVATE LIMIT | AI12: 2408402 | AJ12: Vendor Reconciliation Account - Domestic | AK12: 0 | AL12: 21 | AM12: S | AR12: 07-04-2020 | AS12: 16:14:06 | AT12: 0 | AU12: 64706 | AX12: 2
A13: 1000 | B13: Tata Steel Limited | C13: 44234305 | D13: TDS ON PROVISION | E13: KR | F13: 9000 | G13: 2020 | H13: 12 | I13: 31-03-2020 | J13: 31-03-2020 | K13: -48508 | L13: =K13-Q13+T13 -> -48508 | M13: INR | N13: -48508 | O13: INR | P13: 0 | Q13: 0 | R13: -48508 | S13: 0 | T13: 0 | U13: T040 | V13: TATA BLUESCOPE STEEL PRIVATE LIMIT | X13: TDS on Year End Manual Prov FY 2020 | Y13: TDS on Provisions Manual | Z13: 44234305 | AD13: 2408402 | AE13: Vendor Reconciliation Account - Domestic | AF13: 2405215 | AG13: Provisional Liability for TDS on Povision- Manual | AI13: 2405215 | AJ13: Provisional Liability for TDS on Povision- Manual | AK13: 0 | AL13: 31 | AM13: H | AR13: 07-04-2020 | AS13: 16:14:09 | AT13: 0 | AU13: -48508 | AX13: 3
A14: 1000 | B14: Tata Steel Limited | C14: 44234305 | D14: TDS ON PROVISION | E14: KR | F14: 9000 | G14: 2020 | H14: 12 | I14: 31-03-2020 | J14: 31-03-2020 | K14: 48508 | L14: =K14-Q14+T14 -> 48508 | M14: INR | N14: 48508 | O14: INR | P14: 0 | Q14: 0 | R14: 48508 | S14: 0 | T14: 0 | U14: T040 | V14: TATA BLUESCOPE STEEL PRIVATE LIMIT | X14: TDS on Year End Manual Prov FY 2020 | Y14: TDS on Provisions Manual | Z14: V | AD14: 2408402 | AE14: Vendor Reconciliation Account - Domestic | AF14: T040 | AG14: TATA BLUESCOPE STEEL PRIVATE LIMIT | AI14: 2408402 | AJ14: Vendor Reconciliation Account - Domestic | AK14: 0 | AL14: 21 | AM14: S | AR14: 07-04-2020 | AS14: 16:14:09 | AT14: 0 | AU14: 48508 | AX14: 2
A15: 1000 | B15: Tata Steel Limited | C15: 44234306 | D15: TDS ON PROVISION | E15: KR | F15: 9000 | G15: 2020 | H15: 12 | I15: 31-03-2020 | J15: 31-03-2020 | K15: -5274 | L15: =K15-Q15+T15 -> -5274 | M15: INR | N15: -5274 | O15: INR | P15: 0 | Q15: 0 | R15: -5274 | S15: 0 | T15: 0 | U15: T040 | V15: TATA BLUESCOPE STEEL PRIVATE LIMIT | X15: TDS on Year End Manual Prov FY 2020 | Y15: TDS on Provisions Manual | Z15: 44234306 | AD15: 2408402 | AE15: Vendor Reconciliation Account - Domestic | AF15: 2405215 | AG15: Provisional Liability for TDS on Povision- Manual | AI15: 2405215 | AJ15: Provisional Liability for TDS on Povision- Manual | AK15: 0 | AL15: 31 | AM15: H | AR15: 07-04-2020 | AS15: 16:14:11 | AT15: 0 | AU15: -5274 | AX15: 3
A16: 1000 | B16: Tata Steel Limited | C16: 44234306 | D16: TDS ON PROVISION | E16: KR | F16: 9000 | G16: 2020 | H16: 12 | I16: 31-03-2020 | J16: 31-03-2020 | K16: 5274 | L16: =K16-Q16+T16 -> 5274 | M16: INR | N16: 5274 | O16: INR | P16: 0 | Q16: 0 | R16: 5274 | S16: 0 | T16: 0 | U16: T040 | V16: TATA BLUESCOPE STEEL PRIVATE LIMIT | X16: TDS on Year End Manual Prov FY 2020 | Y16: TDS on Provisions Manual | Z16: V | AD16: 2408402 | AE16: Vendor Reconciliation Account - Domestic | AF16: T040 | AG16: TATA BLUESCOPE STEEL PRIVATE LIMIT | AI16: 2408402 | AJ16: Vendor Reconciliation Account - Domestic | AK16: 0 | AL16: 21 | AM16: S | AR16: 07-04-2020 | AS16: 16:14:11 | AT16: 0 | AU16: 5274 | AX16: 2
A17: 1000 | B17: Tata Steel Limited | C17: 45001676 | D17: R040272105570 | E17: KZ | F17: 5010 | G17: 2020 | H17: 1 | I17: 01-04-2019 | J17: 01-04-2019 | K17: 1996973 | L17: =K17-Q17+T17 -> 1996973 | M17: INR | N17: 1996973 | O17: INR | P17: 0 | Q17: 0 | R17: 1996973 | S17: 0 | T17: 0 | U17: T018 | V17: TATA BLUESCOPE STEEL PRIVATE LIMIT | Y17: 20190401-SERV2 | Z17: 45001676 | AD17: 2408402 | AE17: Vendor Reconciliation Account - Domestic | AF17: 2200403 | AG17: Cash Credit With HDFC- E -Payments Cleared Balance | AI17: 2200403 | AJ17: Cash Credit With HDFC- E -Payments Cleared Balance | AK17: 0 | AL17: 25 | AM17: S | AP17: 45001676 | AQ17: 01-04-2019 | AR17: 01-04-2019 | AS17: 17:51:48 | AT17: 0 | AU17: 1996973 | AX17: 1
A18: 1000 | B18: Tata Steel Limited | C18: 45004518 | D18: R190793184653 | E18: KZ | F18: 9000 | G18: 2020 | H18: 1 | I18: 03-04-2019 | J18: 03-04-2019 | K18: 137519.56 | L18: =K18-Q18+T18 -> 137519.56 | M18: INR | N18: 137519.56 | O18: INR | P18: 0 | Q18: 0 | R18: 137519.56 | S18: 0 | T18: 0 | U18: T040 | V18: TATA BLUESCOPE STEEL PRIVATE LIMIT | Y18: 20190403-KGLO1 | Z18: 45004518 | AD18: 2408402 | AE18: Vendor Reconciliation Account - Domestic | AF18: 2200403 | AG18: Cash Credit With HDFC- E -Payments Cleared Balance | AI18: 2200403 | AJ18: Cash Credit With HDFC- E -Payments Cleared Balance | AK18: 0 | AL18: 25 | AM18: S | AP18: 45004518 | AQ18: 03-04-2019 | AR18: 03-04-2019 | AS18: 12:33:00 | AT18: 0 | AU18: 137519.56 | AX18: 1
A19: 1000 | B19: Tata Steel Limited | C19: 45005501 | D19: R040472484972 | E19: KZ | F19: 9600 | G19: 2020 | H19: 1 | I19: 03-04-2019 | J19: 03-04-2019 | K19: 722969.75 | L19: =K19-Q19+T19 -> 722969.75 | M19: INR | N19: 722969.75 | O19: INR | P19: 0 | Q19: 0 | R19: 722969.75 | S19: 0 | T19: 0 | U19: T018 | V19: TATA BLUESCOPE STEEL PRIVATE LIMIT | Y19: 20190403-SERV2 | Z19: 45005501 | AD19: 2408402 | AE19: Vendor Reconciliation Account - Domestic | AF19: 2200403 | AG19: Cash Credit With HDFC- E -Payments Cleared Balance | AI19: 2200403 | AJ19: Cash Credit With HDFC- E -Payments Cleared Balance | AK19: 0 | AL19: 25 | AM19: S | AP19: 45005501 | AQ19: 03-04-2019 | AR19: 03-04-2019 | AS19: 18:00:55 | AT19: 0 | AU19: 722969.75 | AX19: 2
A20: 1000 | B20: Tata Steel Limited | C20: 45005501 | D20: R040472484972 | E20: KZ | F20: 9600 | G20: 2020 | H20: 1 | I20: 03-04-2019 | J20: 03-04-2019 | K20: 1713145.5 | L20: =K20-Q20+T20 -> 1713145.5 | M20: INR | N20: 1713145.5 | O20: INR | P20: 0 | Q20: 0 | R20: 1713145.5 | S20: 0 | T20: 0 | U20: T018 | V20: TATA BLUESCOPE STEEL PRIVATE LIMIT | Y20: 20190403-SERV2 | Z20: 45005501 | AD20: 2408402 | AE20: Vendor Reconciliation Account - Domestic | AF20: 2200403 | AG20: Cash Credit With HDFC- E -Payments Cleared Balance | AI20: 2200403 | AJ20: Cash Credit With HDFC- E -Payments Cleared Balance | AK20: 0 | AL20: 25 | AM20: S | AP20: 45005501 | AQ20: 03-04-2019 | AR20: 03-04-2019 | AS20: 18:00:55 | AT20: 0 | AU20: 1713145.5 | AX20: 1
A21: 1000 | B21: Tata Steel Limited | C21: 45005501 | D21: R040472484972 | E21: KZ | F21: 9600 | G21: 2020 | H21: 1 | I21: 03-04-2019 | J21: 03-04-2019 | K21: 782591.43 | L21: =K21-Q21+T21 -> 782591.43 | M21: INR | N21: 782591.43 | O21: INR | P21: 0 | Q21: 0 | R21: 782591.43 | S21: 0 | T21: 0 | U21: T018 | V21: TATA BLUESCOPE STEEL PRIVATE LIMIT | Y21: 20190403-SERV2 | Z21: 45005501 | AD21: 2408402 | AE21: Vendor Reconciliation Account - Domestic | AF21: 2200403 | AG21: Cash Credit With HDFC- E -Payments Cleared Balance | AI21: 2200403 | AJ21: Cash Credit With HDFC- E -Payments Cleared Balance | AK21: 0 | AL21: 25 | AM21: S | AP21: 45005501 | AQ21: 03-04-2019 | AR21: 03-04-2019 | AS21: 18:00:55 | AT21: 0 | AU21: 782591.43 | AX21: 3
A22: 1000 | B22: Tata Steel Limited | C22: 45006919 | D22: R040572726149 | E22: KZ | F22: 9600 | G22: 2020 | H22: 1 | I22: 04-04-2019 | J22: 04-04-2019 | K22: 1117660 | L22: =K22-Q22+T22 -> 1117660 | M22: INR | N22: 1117660 | O22: INR | P22: 0 | Q22: 0 | R22: 1117660 | S22: 0 | T22: 0 | U22: T018 | V22: TATA BLUESCOPE STEEL PRIVATE LIMIT | Y22: 20190404-CAPSH | Z22: 45006919 | AD22: 2408402 | AE22: Vendor Reconciliation Account - Domestic | AF22: 2200403 | AG22: Cash Credit With HDFC- E -Payments Cleared Balance | AI22: 2200403 | AJ22: Cash Credit With HDFC- E -Payments Cleared Balance | AK22: 0 | AL22: 25 | AM22: S | AP22: 45006919 | AQ22: 04-04-2019 | AR22: 04-04-2019 | AS22: 17:17:27 | AT22: 0 | AU22: 1117660 | AX22: 1
A23: 1000 | B23: Tata Steel Limited | C23: 45006920 | D23: R040572737139 | E23: KZ | F23: 9000 | G23: 2020 | H23: 1 | I23: 04-04-2019 | J23: 04-04-2019 | K23: 366824.77 | L23: =K23-Q23+T23 -> 366824.77 | M23: INR | N23: 366824.77 | O23: INR | P23: 0 | Q23: 0 | R23: 366824.77 | S23: 0 | T23: 0 | U23: T040 | V23: TATA BLUESCOPE STEEL PRIVATE LIMIT | Y23: 20190404-CAPSH | Z23: 45006920 | AD23: 2408402 | AE23: Vendor Reconciliation Account - Domestic | AF23: 2200403 | AG23: Cash Credit With HDFC- E -Payments Cleared Balance | AI23: 2200403 | AJ23: Cash Credit With HDFC- E -Payments Cleared Balance | AK23: 0 | AL23: 25 | AM23: S | AP23: 45006920 | AQ23: 04-04-2019 | AR23: 04-04-2019 | AS23: 17:17:27 | AT23: 0 | AU23: 366824.77 | AX23: 1
A24: 1000 | B24: Tata Steel Limited | C24: 45007443 | D24: R040872990802 | E24: KZ | F24: 5010 | G24: 2020 | H24: 1 | I24: 05-04-2019 | J24: 05-04-2019 | K24: 646758 | L24: =K24-Q24+T24 -> 646758 | M24: INR | N24: 646758 | O24: INR | P24: 0 | Q24: 0 | R24: 646758 | S24: 0 | T24: 0 | U24: T018 | V24: TATA BLUESCOPE STEEL PRIVATE LIMIT | Y24: 20190405-SERV2 | Z24: 45007443 | AD24: 2408402 | AE24: Vendor Reconciliation Account - Domestic | AF24: 2200403 | AG24: Cash Credit With HDFC- E -Payments Cleared Balance | AI24: 2200403 | AJ24: Cash Credit With HDFC- E -Payments Cleared Balance | AK24: 0 | AL24: 25 | AM24: S | AP24: 45007443 | AQ24: 05-04-2019 | AR24: 05-04-2019 | AS24: 12:44:05 | AT24: 0 | AU24: 646758 | AX24: 1
A25: 1000 | B25: Tata Steel Limited | C25: 45007445 | D25: R040872990805 | E25: KZ | F25: 9500 | G25: 2020 | H25: 1 | I25: 05-04-2019 | J25: 05-04-2019 | K25: 966445.92 | L25: =K25-Q25+T25 -> 966445.92 | M25: INR | N25: 966445.92 | O25: INR | P25: 0 | Q25: 0 | R25: 966445.92 | S25: 0 | T25: 0 | U25: T040 | V25: TATA BLUESCOPE STEEL PRIVATE LIMIT | Y25: 20190405-SERV2 | Z25: 45007445 | AD25: 2408402 | AE25: Vendor Reconciliation Account - Domestic | AF25: 2200403 | AG25: Cash Credit With HDFC- E -Payments Cleared Balance | AI25: 2200403 | AJ25: Cash Credit With HDFC- E -Payments Cleared Balance | AK25: 0 | AL25: 25 | AM25: S | AP25: 45007445 | AQ25: 05-04-2019 | AR25: 05-04-2019 | AS25: 12:44:05 | AT25: 0 | AU25: 966445.92 | AX25: 1
A26: 1000 | B26: Tata Steel Limited | C26: 45010166 | D26: R041073347232 | E26: KZ | F26: 0920 | G26: 2020 | H26: 1 | I26: 09-04-2019 | J26: 09-04-2019 | K26: 5121003.3 | L26: =K26-Q26+T26 -> 5121003.3 | M26: INR | N26: 5121003.3 | O26: INR | P26: 0 | Q26: 0 | R26: 5121003.3 | S26: 0 | T26: 0 | U26: T018 | V26: TATA BLUESCOPE STEEL PRIVATE LIMIT | Y26: 20190409-COPS3 | Z26: 45010166 | AD26: 2408402 | AE26: Vendor Reconciliation Account - Domestic | AF26: 2200403 | AG26: Cash Credit With HDFC- E -Payments Cleared Balance | AI26: 2200403 | AJ26: Cash Credit With HDFC- E -Payments Cleared Balance | AK26: 0 | AL26: 25 | AM26: S | AP26: 45010166 | AQ26: 09-04-2019 | AR26: 09-04-2019 | AS26: 15:25:25 | AT26: 0 | AU26: 5121003.3 | AX26: 1
A27: 1000 | B27: Tata Steel Limited | C27: 45012116 | D27: R190800737014 | E27: KZ | F27: 9000 | G27: 2020 | H27: 1 | I27: 11-04-2019 | J27: 11-04-2019 | K27: -162273.6 | L27: =K27-Q27+T27 -> -162273.6 | M27: INR | N27: -162273.6 | O27: INR | P27: 0 | Q27: 0 | R27: -162273.6 | S27: 0 | T27: 0 | U27: T040 | V27: TATA BLUESCOPE STEEL PRIVATE LIMIT | Y27: 20190411-SERV3 | Z27: 45012116 | AD27: 2408402 | AE27: Vendor Reconciliation Account - Domestic | AF27: T040 | AG27: TATA BLUESCOPE STEEL PRIVATE LIMIT | AI27: 2408402 | AJ27: Vendor Reconciliation Account - Domestic | AK27: 0 | AL27: 38 | AM27: H | AP27: 45012116 | AQ27: 11-04-2019 | AR27: 11-04-2019 | AS27: 14:26:08 | AT27: 0 | AU27: -162273.6 | AX27: 1
A28: 1000 | B28: Tata Steel Limited | C28: 45012116 | D28: R190800737014 | E28: KZ | F28: 9500 | G28: 2020 | H28: 1 | I28: 11-04-2019 | J28: 11-04-2019 | K28: 189092.68 | L28: =K28-Q28+T28 -> 189092.68 | M28: INR | N28: 189092.68 | O28: INR | P28: 0 | Q28: 0 | R28: 189092.68 | S28: 0 | T28: 0 | U28: T040 | V28: TATA BLUESCOPE STEEL PRIVATE LIMIT | Y28: 20190411-SERV3 | Z28: 45012116 | AD28: 2408402 | AE28: Vendor Reconciliation Account - Domestic | AF28: T040 | AG28: TATA BLUESCOPE STEEL PRIVATE LIMIT | AI28: 2408402 | AJ28: Vendor Reconciliation Account - Domestic | AK28: 0 | AL28: 25 | AM28: S | AP28: 45012116 | AQ28: 11-04-2019 | AR28: 11-04-2019 | AS28: 14:26:08 | AT28: 0 | AU28: 189092.68 | AX28: 2
... A160: 1000 | B160: Tata Steel Limited | C160: 45262199 | D160: R031674248390 | E160: KZ | F160: 9600 | G160: 2020 | H160: 12 | I160: 13-03-2020 | J160: 13-03-2020 | K160: 600451.7 | L160: =K160-Q160+T160 -> 600451.7 | M160: INR | N160: 600451.7 | O160: INR | P160: 0 | Q160: 0 | R160: 600451.7 | S160: 0 | T160: 0 | U160: T040 | V160: TATA BLUESCOPE STEEL PRIVATE LIMIT | Y160: 20200313-CAPSH | Z160: 45262199 | AD160: 2408402 | AE160: Vendor Reconciliation Account - Domestic | AF160: 2200403 | AG160: Cash Credit With HDFC- E -Payments Cleared Balance | AI160: 2200403 | AJ160: Cash Credit With HDFC- E -Payments Cleared Balance | AK160: 0 | AL160: 25 | AM160: S | AP160: 45262199 | AQ160: 13-03-2020 | AR160: 13-03-2020 | AS160: 14:56:16 | AT160: 0 | AU160: 600451.7 | AX160: 1
A161: 1000 | B161: Tata Steel Limited | C161: 51007775 | D161: CI0004108029 | E161: RE | F161: 9600 | G161: 2020 | H161: 1 | I161: 43529 | J161: 43558 | K161: -110831.38 | L161: =K161-Q161+T161 -> -93924.9 | M161: INR | N161: -110831.38 | O161: INR | P161: -110831.38 | Q161: -16906.48 | R161: -93924.9 | S161: 0 | T161: 0 | U161: T018 | V161: TATA BLUESCOPE STEEL PRIVATE LIMIT | Y161: 2300047310 | Z161: 51007775 | AB161: 2300047310 | AD161: 2408402 | AE161: Vendor Reconciliation Account - Domestic | AF161: 2408424 | AG161: GR/IR Account - Capital (Project System) | AH161: 5149121 | AI161: 5149121 | AJ161: Purchase of Capital goods-Project System | AK161: 0 | AL161: 31 | AM161: H | AP161: 45018260 | AQ161: 16-04-2019 | AR161: 03-04-2019 | AS161: 17:10:51 | AT161: 0 | AU161: -110831.38 | AX161: 1
A162: 1000 | B162: Tata Steel Limited | C162: 51015501 | D162: CI0004107732 | E162: RE | F162: 5030 | G162: 2020 | H162: 1 | I162: 43519 | J162: 43563 | K162: -3510796.2 | L162: =K162-Q162+T162 -> -2975250.9 | M162: INR | N162: -3510796.2 | O162: INR | P162: -3510796.2 | Q162: -535545.29 | R162: -2975250.9 | S162: 0 | T162: 0 | U162: T018 | V162: TATA BLUESCOPE STEEL PRIVATE LIMIT | X162: Bill Receipt Date :22.03.2019 | Y162: 3700786376 | Z162: 51015501 | AB162: 3700786376 | AD162: 2408402 | AE162: Vendor Reconciliation Account - Domestic | AF162: 2408409 | AG162: Gr/Ir For Stores And Spares | AH162: 6005101 | AI162: 6005101 | AJ162: Purchase of Stores | AK162: 0 | AL162: 31 | AM162: H | AP162: 45012359 | AQ162: 11-04-2019 | AR162: 08-04-2019 | AS162: 10:39:26 | AT162: 0 | AU162: -3510796.2 | AX162: 1
A163: 1000 | B163: Tata Steel Limited | C163: 51017855 | D163: OM/ARC/14 | E163: RE | F163: 9600 | G163: 2020 | H163: 1 | I163: 43551 | J163: 43564 | K163: -425053.85 | L163: =K163-Q163+T163 -> -366426.01 | M163: INR | N163: -425053.85 | O163: INR | P163: -432382.69 | Q163: -65956.68 | R163: -359097.17 | S163: -366426.01 | T163: -7328.84 | U163: T018 | V163: TATA BLUESCOPE STEEL PRIVATE LIMIT | X163: SUPPLY AND FIXING OF SHEET | Y163: 4404339865 | Z163: 51017855 | AB163: 4404339865 | AD163: 2408402 | AE163: Vendor Reconciliation Account - Domestic | AF163: 2408422 | AG163: GR/IR Account - Services & Capital | AH163: 5149027 | AI163: 5149027 | AJ163: Civil Contract Jobs | AK163: 0 | AL163: 31 | AM163: H | AP163: 45036233 | AQ163: 07-05-2019 | AR163: 09-04-2019 | AS163: 09:31:44 | AT163: 0 | AU163: -425053.85 | AX163: 2
A164: 1000 | B164: Tata Steel Limited | C164: 51017855 | D164: OM/ARC/14 | E164: RE | F164: 9600 | G164: 2020 | H164: 1 | I164: 43551 | J164: 43564 | K164: -215527.83 | L164: =K164-Q164+T164 -> -185799.99 | M164: INR | N164: -215527.83 | O164: INR | P164: -219243.99 | Q164: -33444 | R164: -182083.83 | S164: -185799.99 | T164: -3716.16 | U164: T018 | V164: TATA BLUESCOPE STEEL PRIVATE LIMIT | X164: SUPPLY AND FIXING OF SHEET | Y164: 4404339865 | Z164: 51017855 | AB164: 4404339865 | AD164: 2408402 | AE164: Vendor Reconciliation Account - Domestic | AF164: 2408422 | AG164: GR/IR Account - Services & Capital | AH164: 5149027 | AI164: 5149027 | AJ164: Civil Contract Jobs | AK164: 0 | AL164: 31 | AM164: H | AP164: 45036233 | AQ164: 07-05-2019 | AR164: 09-04-2019 | AS164: 09:31:44 | AT164: 0 | AU164: -215527.83 | AX164: 1
A165: 1000 | B165: Tata Steel Limited | C165: 51017865 | D165: OM/ARC/15 | E165: RE | F165: 9600 | G165: 2020 | H165: 1 | I165: 43551 | J165: 43564 | K165: -208614.2 | L165: =K165-Q165+T165 -> -179840 | M165: INR | N165: -208614.2 | O165: INR | P165: -212211.2 | Q165: -32371.2 | R165: -176243 | S165: -179840 | T165: -3597 | U165: T018 | V165: TATA BLUESCOPE STEEL PRIVATE LIMIT | X165: SUPPLY AND FIXING OF SHEET | Y165: 4404338210 | Z165: 51017865 | AB165: 4404338210 | AD165: 2408402 | AE165: Vendor Reconciliation Account - Domestic | AF165: 2408422 | AG165: GR/IR Account - Services & Capital | AH165: 5149027 | AI165: 5149027 | AJ165: Civil Contract Jobs | AK165: 0 | AL165: 31 | AM165: H | AP165: 45036233 | AQ165: 07-05-2019 | AR165: 09-04-2019 | AS165: 09:35:09 | AT165: 0 | AU165: -208614.2 | AX165: 1
A166: 1000 | B166: Tata Steel Limited | C166: 51017868 | D166: OM/ARC/16 | E166: RE | F166: 9600 | G166: 2020 | H166: 1 | I166: 43551 | J166: 43564 | K166: -106070.26 | L166: =K166-Q166+T166 -> -91440 | M166: INR | N166: -106070.26 | O166: INR | P166: -107899.2 | Q166: -16459.2 | R166: -89611.06 | S166: -91440 | T166: -1828.94 | U166: T018 | V166: TATA BLUESCOPE STEEL PRIVATE LIMIT | X166: SUPPLY AND FIXING OF SHEET | Y166: 4404338208 | Z166: 51017868 | AB166: 4404338208 | AD166: 2408402 | AE166: Vendor Reconciliation Account - Domestic | AF166: 2408422 | AG166: GR/IR Account - Services & Capital | AH166: 5149027 | AI166: 5149027 | AJ166: Civil Contract Jobs | AK166: 0 | AL166: 31 | AM166: H | AP166: 45036233 | AQ166: 07-05-2019 | AR166: 09-04-2019 | AS166: 09:37:32 | AT166: 0 | AU166: -106070.26 | AX166: 3
A167: 1000 | B167: Tata Steel Limited | C167: 51017868 | D167: OM/ARC/16 | E167: RE | F167: 9600 | G167: 2020 | H167: 1 | I167: 43551 | J167: 43564 | K167: -129212.23 | L167: =K167-Q167+T167 -> -111390 | M167: INR | N167: -129212.23 | O167: INR | P167: -131440.2 | Q167: -20050.2 | R167: -109162.03 | S167: -111390 | T167: -2227.97 | U167: T018 | V167: TATA BLUESCOPE STEEL PRIVATE LIMIT | X167: SUPPLY AND FIXING OF SHEET | Y167: 4404338208 | Z167: 51017868 | AB167: 4404338208 | AD167: 2408402 | AE167: Vendor Reconciliation Account - Domestic | AF167: 2408422 | AG167: GR/IR Account - Services & Capital | AH167: 5149027 | AI167: 5149027 | AJ167: Civil Contract Jobs | AK167: 0 | AL167: 31 | AM167: H | AP167: 45036233 | AQ167: 07-05-2019 | AR167: 09-04-2019 | AS167: 09:37:32 | AT167: 0 | AU167: -129212.23 | AX167: 2
A168: 1000 | B168: Tata Steel Limited | C168: 51017868 | D168: OM/ARC/16 | E168: RE | F168: 9600 | G168: 2020 | H168: 1 | I168: 43551 | J168: 43564 | K168: -68903.91 | L168: =K168-Q168+T168 -> -59400 | M168: INR | N168: -68903.91 | O168: INR | P168: -70092 | Q168: -10692 | R168: -58211.91 | S168: -59400 | T168: -1188.09 | U168: T018 | V168: TATA BLUESCOPE STEEL PRIVATE LIMIT | X168: SUPPLY AND FIXING OF SHEET | Y168: 4404338208 | Z168: 51017868 | AB168: 4404338208 | AD168: 2408402 | AE168: Vendor Reconciliation Account - Domestic | AF168: 2408422 | AG168: GR/IR Account - Services & Capital | AH168: 5149027 | AI168: 5149027 | AJ168: Civil Contract Jobs | AK168: 0 | AL168: 31 | AM168: H | AP168: 45036233 | AQ168: 07-05-2019 | AR168: 09-04-2019 | AS168: 09:37:32 | AT168: 0 | AU168: -68903.91 | AX168: 1
A169: 1000 | B169: Tata Steel Limited | C169: 51017875 | D169: OM/ARC/17 | E169: RE | F169: 9600 | G169: 2020 | H169: 1 | I169: 43551 | J169: 43564 | K169: -414990 | L169: =K169-Q169+T169 -> -357750 | M169: INR | N169: -414990 | O169: INR | P169: -422145 | Q169: -64395 | R169: -350595 | S169: -357750 | T169: -7155 | U169: T018 | V169: TATA BLUESCOPE STEEL PRIVATE LIMIT | X169: SUPPLY AND FIXING OF SHEET | Y169: 4404338209 | Z169: 51017875 | AB169: 4404338209 | AD169: 2408402 | AE169: Vendor Reconciliation Account - Domestic | AF169: 2408422 | AG169: GR/IR Account - Services & Capital | AH169: 5149027 | AI169: 5149027 | AJ169: Civil Contract Jobs | AK169: 0 | AL169: 31 | AM169: H | AP169: 45036233 | AQ169: 07-05-2019 | AR169: 09-04-2019 | AS169: 09:40:06 | AT169: 0 | AU169: -414990 | AX169: 1
A170: 1000 | B170: Tata Steel Limited | C170: 51019236 | D170: CI0004108179 | E170: RE | F170: 5030 | G170: 2020 | H170: 1 | I170: 43537 | J170: 43564 | K170: -1844550.3 | L170: =K170-Q170+T170 -> -1563178.4 | M170: INR | N170: -1844550.3 | O170: INR | P170: -1844550.3 | Q170: -281371.99 | R170: -1563178.4 | S170: 0 | T170: 0 | U170: T018 | V170: TATA BLUESCOPE STEEL PRIVATE LIMIT | X170: Bill Receipt Date :22.03.2019 | Y170: 4404040292 | Z170: 51019236 | AB170: 4404040292 | AD170: 2408402 | AE170: Vendor Reconciliation Account - Domestic | AF170: 2408409 | AG170: Gr/Ir For Stores And Spares | AH170: 6005101 | AI170: 6005101 | AJ170: Purchase of Stores | AK170: 0 | AL170: 31 | AM170: H | AP170: 45019034 | AQ170: 16-04-2019 | AR170: 09-04-2019 | AS170: 15:39:51 | AT170: 0 | AU170: -1844550.3 | AX170: 1
A171: 1000 | B171: Tata Steel Limited | C171: 51019944 | D171: CI0004107087 | E171: RE | F171: 9600 | G171: 2020 | H171: 1 | I171: 43492 | J171: 43565 | K171: -309.75 | L171: =K171-Q171+T171 -> -262.5 | M171: INR | N171: -309.75 | O171: INR | P171: -309.75 | Q171: -47.25 | R171: -262.5 | S171: 0 | T171: 0 | U171: T040 | V171: TATA BLUESCOPE STEEL PRIVATE LIMIT | Y171: 2300049475 | Z171: 51019944 | AB171: 2300049475 | AD171: 2408402 | AE171: Vendor Reconciliation Account - Domestic | AF171: 2408424 | AG171: GR/IR Account - Capital (Project System) | AH171: 5149121 | AI171: 5149121 | AJ171: Purchase of Capital goods-Project System | AK171: 0 | AL171: 31 | AM171: H | AP171: 45020062 | AQ171: 17-04-2019 | AR171: 10-04-2019 | AS171: 09:20:14 | AT171: 0 | AU171: -309.75 | AX171: 1
...

Sheet TBSL
A1: Company_Code | B1: Company_Name | C1: SAP_Doc_Number | D1: Reference | E1: Document_Type | F1: Business_Area | G1: Fiscal_Year | H1: Posting_Period | I1: DocChq_Date | J1: Posting_Date | K1: Amount_in_Local_Currency | L1: SOA | M1: Local_Currency | N1: Amount_in_Document_Currency | O1: Document_Currency | P1: Discount_Base_Amount | Q1: GST_Amount | R1: Net_Amount | S1: Withholding_Tax_Base_Amount | T1: Withholding_Tax_Amount | U1: VendorCustomer | V1: VendorCustomer_Name | W1: Trading_Partner | X1: Text_ | Y1: HDR_Text | Z1: InvSO_Reference | AA1: Plant | AB1: Purchasing_Document | AC1: Delivery_Note | AD1: Account | AE1: Account_Description | AF1: Offsetting_Account | AG1: Offsetting_Acct_Name | AH1: GRIR_Offsetting_Account | AI1: Final_Offsetting_Account | AJ1: Final_Offsetting_Acct_Name | AK1: WBS_Element | AL1: Posting_Key | AM1: DebitCredit | AN1: Special_GL_Ind | AO1: Reversal_Indicator | AP1: Clearing_Doc | AQ1: Clearing_Date | AR1: Entry_date | AS1: Entry_Time | AT1: Notional_GST | AU1: Gross_Amount_In_Local_Currency | AV1: DE_Indicator | AW1: PO_Line | AX1: Entry_Line
A2: 1000 | B2: Tata BlueScope Steel Ltd | C2: 100058209 | E2: AB | F2: 1109 | G2: 2019 | H2: 4 | I2: 43677 | J2: 43677 | K2: 463358.86 | L2: =K2-Q2+T2 -> 463358.86 | M2: INR | N2: 463358.86 | O2: INR | P2: 0 | Q2: 0 | R2: 463358.86 | S2: 0 | T2: 0 | U2: 312193 | V2: Tata Steel Limited ( Kalinganagar) | X2: SI1904100019 | Z2: 2316 | AB2: 4700069343/172 | AD2: 110000 | AE2: Customer - Domestic | AF2: 110000 | AG2: Customer - Domestic | AI2: 110000 | AJ2: Customer - Domestic | AK2: 0 | AL2: 4 | AM2: S | AP2: 100058463 | AQ2: 43677 | AR2: 43678 | AS2: 0.19703704 | AT2: 0 | AU2: 0 | AX2: 2
A3: 1000 | B3: Tata BlueScope Steel Ltd | C3: 100082045 | E3: AB | F3: 1101 | G3: 2019 | H3: 5 | I3: 43708 | J3: 43708 | K3: 74051 | L3: =K3-Q3+T3 -> 74051 | M3: INR | N3: 74051 | O3: INR | P3: 0 | Q3: 0 | R3: 74051 | S3: 0 | T3: 0 | U3: 318999 | V3: Tata Steel Limited | X3: Short Payment Aug 19 | Z3: 100082045 | AD3: 110000 | AE3: Customer - Domestic | AF3: 110000 | AG3: Customer - Domestic | AI3: 110000 | AJ3: Customer - Domestic | AK3: 0 | AL3: 4 | AM3: S | AR3: 43710 | AS3: 0.35267361 | AT3: 0 | AU3: 0 | AX3: 3
A4: 1000 | B4: Tata BlueScope Steel Ltd | C4: 100075998 | E4: AB | F4: 1101 | G4: 2019 | H4: 5 | I4: 43703 | J4: 43703 | K4: -6259900 | L4: =K4-Q4+T4 -> -6259900 | M4: INR | N4: -6259900 | O4: INR | P4: 0 | Q4: 0 | R4: -6259900 | S4: 0 | T4: 0 | U4: 309728 | V4: Tata Steel Ltd - Growth Shop | Z4: 100075998 | AD4: 110000 | AE4: Customer - Domestic | AF4: 310300 | AG4: Customer - Advance against Sale | AI4: 310300 | AJ4: Customer - Advance against Sale | AK4: 0 | AL4: 17 | AM4: H | AP4: 100075998 | AQ4: 43703 | AR4: 43703 | AS4: 0.73967593 | AT4: 0 | AU4: 0 | AX4: 1
A5: 1000 | B5: Tata BlueScope Steel Ltd | C5: 113598 | D5: 95004888 | E5: RV | F5: 1109 | G5: 2019 | H5: 12 | I5: 43893 | J5: 43893 | K5: 444919 | L5: =K5-Q5+T5 -> 377050 | M5: INR | N5: 444919 | O5: INR | P5: 0 | Q5: 67869 | R5: 377050 | S5: 0 | T5: 0 | U5: 312193 | V5: Tata Steel Limited ( Kalinganagar) | Z5: 2525 | AB5: SI1904100055 | AD5: 110000 | AE5: Customer - Domestic | AF5: 501020 | AG5: Revenue DS - Sale of Services Domestic | AI5: 501020 | AJ5: Revenue DS - Sale of Services Domestic | AK5: 0 | AL5: 1 | AM5: S | AR5: 43893 | AS5: 0.59444444 | AT5: 0 | AU5: 0 | AW5: 0 | AX5: 1
A6: 1000 | B6: Tata BlueScope Steel Ltd | C6: 113643 | D6: 95004889 | E6: RV | F6: 1109 | G6: 2019 | H6: 12 | I6: 43895 | J6: 43895 | K6: 570730.6 | L6: =K6-Q6+T6 -> 483670 | M6: INR | N6: 570730.6 | O6: INR | P6: 0 | Q6: 87060.6 | R6: 483670 | S6: 0 | T6: 0 | U6: 312193 | V6: Tata Steel Limited ( Kalinganagar) | Z6: 2525 | AB6: SI1904100056 | AD6: 110000 | AE6: Customer - Domestic | AF6: 501020 | AG6: Revenue DS - Sale of Services Domestic | AI6: 501020 | AJ6: Revenue DS - Sale of Services Domestic | AK6: 0 | AL6: 1 | AM6: S | AR6: 43895 | AS6: 0.77569444 | AT6: 0 | AU6: 0 | AW6: 0 | AX6: 1
A7: 1000 | B7: Tata BlueScope Steel Ltd | C7: 1400006405 | E7: DZ | F7: 1106 | G7: 2019 | H7: 6 | I7: 43738 | J7: 43738 | K7: -5496781.8 | L7: =K7-Q7+T7 -> -5496781.8 | M7: INR | N7: -5496781.8 | O7: INR | P7: 0 | Q7: 0 | R7: -5496781.8 | S7: 0 | T7: 0 | U7: 305576 | V7: Tata Steel Ltd. | X7: IL36701909309640|HDFCR52019093 | Y7: IL36701909309640|HDFCR520 | Z7: 1400006405 | AC7: Receipt | AD7: 310300 | AE7: Customer - Advance against Sale | AF7: 101105 | AG7: Stanchart- Clearing Pune | AI7: 101105 | AJ7: Stanchart- Clearing Pune | AK7: 0 | AL7: 19 | AM7: H | AN7: A | AP7: 100122444 | AQ7: 43738 | AR7: 43739 | AS7: 0.4278125 | AT7: 0 | AU7: 0 | AX7: 2
A8: 1000 | B8: Tata BlueScope Steel Ltd | C8: 100882 | D8: SI1904100005 | E8: RV | F8: 1109 | G8: 2019 | H8: 1 | I8: 43581 | J8: 43581 | K8: 651626.68 | L8: =K8-Q8+T8 -> 552226 | M8: INR | N8: 651626.68 | O8: INR | P8: 0 | Q8: 99400.68 | R8: 552226 | S8: 0 | T8: 0 | U8: 312193 | V8: Tata Steel Limited ( Kalinganagar) | Z8: 2316 | AB8: 4700069343/172 | AD8: 110000 | AE8: Customer - Domestic | AF8: 501020 | AG8: Revenue DS - Sale of Services Domestic | AI8: 501020 | AJ8: Revenue DS - Sale of Services Domestic | AK8: 0 | AL8: 1 | AM8: S | AP8: 100005107 | AQ8: 43585 | AR8: 43581 | AS8: 0.77087963 | AT8: 0 | AU8: 0 | AX8: 1
A9: 1000 | B9: Tata BlueScope Steel Ltd | C9: 100057890 | E9: AB | F9: 1109 | G9: 2019 | H9: 4 | I9: 43677 | J9: 43677 | K9: 7696 | L9: =K9-Q9+T9 -> 7696 | M9: INR | N9: 7696 | O9: INR | P9: 0 | Q9: 0 | R9: 7696 | S9: 0 | T9: 0 | U9: 312193 | V9: Tata Steel Limited ( Kalinganagar) | X9: TDS SI1904100016 | Z9: 2316 | AB9: 4700069343/172 | AD9: 110000 | AE9: Customer - Domestic | AF9: 110000 | AG9: Customer - Domestic | AI9: 110000 | AJ9: Customer - Domestic | AK9: 0 | AL9: 4 | AM9: S | AP9: 100173563 | AQ9: 43799 | AR9: 43677 | AS9: 0.62208333 | AT9: 0 | AU9: 0 | AX9: 4
A10: 1000 | B10: Tata BlueScope Steel Ltd | C10: 100078765 | E10: AB | F10: 1108 | G10: 2019 | H10: 5 | I10: 43706 | J10: 43706 | K10: -210068.32 | L10: =K10-Q10+T10 -> -210068.32 | M10: INR | N10: -210068.32 | O10: INR | P10: 0 | Q10: 0 | R10: -210068.32 | S10: 0 | T10: 0 | U10: 312193 | V10: Tata Steel Limited ( Kalinganagar) | Z10: 100078765 | AD10: 110000 | AE10: Customer - Domestic | AF10: 110000 | AG10: Customer - Domestic | AI10: 110000 | AJ10: Customer - Domestic | AK10: 0 | AL10: 17 | AM10: H | AP10: 100078765 | AQ10: 43706 | AR10: 43706 | AS10: 0.70283565 | AT10: 0 | AU10: 0 | AX10: 8
A11: 1000 | B11: Tata BlueScope Steel Ltd | C11: 1400003713 | E11: DZ | F11: 1106 | G11: 2019 | H11: 4 | I11: 43654 | J11: 43654 | K11: -844942.76 | L11: =K11-Q11+T11 -> -844942.76 | M11: INR | N11: -844942.76 | O11: INR | P11: 0 | Q11: 0 | R11: -844942.76 | S11: 0 | T11: 0 | U11: 305576 | V11: Tata Steel Ltd. | X11: IL36701907081828|HDFCR52019070 | Y11: IL36701907081828|HDFCR520 | Z11: 1400003713 | AC11: Receipt | AD11: 310300 | AE11: Customer - Advance against Sale | AF11: 101105 | AG11: Stanchart- Clearing Pune | AI11: 101105 | AJ11: Stanchart- Clearing Pune | AK11: 0 | AL11: 19 | AM11: H | AN11: A | AP11: 100057905 | AQ11: 43677 | AR11: 43656 | AS11: 0.27262731 | AT11: 0 | AU11: 0 | AX11: 2
A12: 1000 | B12: Tata BlueScope Steel Ltd | C12: 100057905 | E12: AB | F12: 1106 | G12: 2019 | H12: 4 | I12: 43677 | J12: 43677 | K12: 3199939.6 | L12: =K12-Q12+T12 -> 3199939.6 | M12: INR | N12: 3199939.6 | O12: INR | P12: 0 | Q12: 0 | R12: 3199939.6 | S12: 0 | T12: 0 | U12: 305576 | V12: Tata Steel Ltd. | Z12: 100057905 | AD12: 310300 | AE12: Customer - Advance against Sale | AF12: 310300 | AG12: Customer - Advance against Sale | AI12: 310300 | AJ12: Customer - Advance against Sale | AK12: 0 | AL12: 9 | AM12: S | AN12: A | AP12: 100057905 | AQ12: 43677 | AR12: 43677 | AS12: 0.661875 | AT12: 0 | AU12: 0 | AX12: 3
A13: 1000 | B13: Tata BlueScope Steel Ltd | C13: 100058185 | E13: AB | F13: 1106 | G13: 2019 | H13: 4 | I13: 43677 | J13: 43677 | K13: 774670 | L13: =K13-Q13+T13 -> 774670 | M13: INR | N13: 774670 | O13: INR | P13: 0 | Q13: 0 | R13: 774670 | S13: 0 | T13: 0 | U13: 305576 | V13: Tata Steel Ltd. | Z13: 100058185 | AD13: 310300 | AE13: Customer - Advance against Sale | AF13: 110000 | AG13: Customer - Domestic | AI13: 110000 | AJ13: Customer - Domestic | AK13: 0 | AL13: 9 | AM13: S | AN13: A | AP13: 100058185 | AQ13: 43677 | AR13: 43678 | AS13: 0.17371528 | AT13: 0 | AU13: 0 | AX13: 2
A14: 1000 | B14: Tata BlueScope Steel Ltd | C14: 113741 | D14: 95004891 | E14: RV | F14: 1109 | G14: 2019 | H14: 12 | I14: 43899 | J14: 43899 | K14: 533737.6 | L14: =K14-Q14+T14 -> 452320 | M14: INR | N14: 533737.6 | O14: INR | P14: 0 | Q14: 81417.6 | R14: 452320 | S14: 0 | T14: 0 | U14: 312193 | V14: Tata Steel Limited ( Kalinganagar) | Z14: 2525 | AB14: SI1904100058 | AD14: 110000 | AE14: Customer - Domestic | AF14: 501020 | AG14: Revenue DS - Sale of Services Domestic | AI14: 501020 | AJ14: Revenue DS - Sale of Services Domestic | AK14: 0 | AL14: 1 | AM14: S | AR14: 43899 | AS14: 0.68680556 | AT14: 0 | AU14: 0 | AW14: 0 | AX14: 1
A15: 1000 | B15: Tata BlueScope Steel Ltd | C15: 105301 | D15: CN1901100024 | E15: RV | F15: 1108 | G15: 2019 | H15: 4 | I15: 43677 | J15: 43677 | K15: -10620 | L15: =K15-Q15+T15 -> -9000 | M15: INR | N15: -10620 | O15: INR | P15: 0 | Q15: -1620 | R15: -9000 | S15: 0 | T15: 0 | U15: 312948 | V15: Tata Steel Limited, �Wire Division | Z15: 60002464 | AD15: 110000 | AE15: Customer - Domestic | AF15: 901000 | AG15: Freight DS - Domestic | AI15: 901000 | AJ15: Freight DS - Domestic | AK15: 0 | AL15: 11 | AM15: H | AP15: 100058213 | AQ15: 43677 | AR15: 43677 | AS15: 0.53966435 | AT15: 0 | AU15: 0 | AX15: 1
A16: 1000 | B16: Tata BlueScope Steel Ltd | C16: 100116355 | E16: AB | F16: 1108 | G16: 2019 | H16: 6 | I16: 43738 | J16: 43738 | K16: -735858.32 | L16: =K16-Q16+T16 -> -735858.32 | M16: INR | N16: -735858.32 | O16: INR | P16: 0 | Q16: 0 | R16: -735858.32 | S16: 0 | T16: 0 | U16: 312193 | V16: Tata Steel Limited ( Kalinganagar) | Z16: 100116355 | AD16: 110000 | AE16: Customer - Domestic | AF16: 110000 | AG16: Customer - Domestic | AI16: 110000 | AJ16: Customer - Domestic | AK16: 0 | AL16: 17 | AM16: H | AP16: 100116355 | AQ16: 43738 | AR16: 43738 | AS16: 0.22452546 | AT16: 0 | AU16: 0 | AX16: 6
A17: 1000 | B17: Tata BlueScope Steel Ltd | C17: 100081981 | E17: AB | F17: 1101 | G17: 2019 | H17: 5 | I17: 43708 | J17: 43708 | K17: -2478000 | L17: =K17-Q17+T17 -> -2478000 | M17: INR | N17: -2478000 | O17: INR | P17: 0 | Q17: 0 | R17: -2478000 | S17: 0 | T17: 0 | U17: 309728 | V17: Tata Steel Ltd - Growth Shop | Z17: 100081981 | AD17: 110000 | AE17: Customer - Domestic | AF17: 310300 | AG17: Customer - Advance against Sale | AI17: 310300 | AJ17: Customer - Advance against Sale | AK17: 0 | AL17: 17 | AM17: H | AP17: 100081981 | AQ17: 43708 | AR17: 43710 | AS17: 0.28978009 | AT17: 0 | AU17: 0 | AX17: 1
A18: 1000 | B18: Tata BlueScope Steel Ltd | C18: 100058228 | E18: AB | F18: 1102 | G18: 2019 | H18: 4 | I18: 43677 | J18: 43677 | K18: -24754.04 | L18: =K18-Q18+T18 -> -24754.04 | M18: INR | N18: -24754.04 | O18: INR | P18: 0 | Q18: 0 | R18: -24754.04 | S18: 0 | T18: 0 | U18: 315113 | V18: Tata Steel Limited | Z18: 100058228 | AD18: 110000 | AE18: Customer - Domestic | AF18: 310300 | AG18: Customer - Advance against Sale | AI18: 310300 | AJ18: Customer - Advance against Sale | AK18: 0 | AL18: 17 | AM18: H | AP18: 100058228 | AQ18: 43677 | AR18: 43678 | AS18: 0.20967593 | AT18: 0 | AU18: 0 | AX18: 1
A19: 1000 | B19: Tata BlueScope Steel Ltd | C19: 1600000142 | D19: GST CREDIT ENTRY | E19: DA | F19: 1106 | G19: 2019 | H19: 4 | I19: 43676 | J19: 43676 | K19: -24754.04 | L19: =K19-Q19+T19 -> -24754.04 | M19: INR | N19: -24754.04 | O19: INR | P19: -24754.04 | Q19: 0 | R19: -24754.04 | S19: 0 | T19: 0 | U19: 315113 | V19: Tata Steel Limited | X19: IGST on LD Tata Steel | Y19: GST Credit TSL LD | Z19: 1600000142 | AD19: 310300 | AE19: Customer - Advance against Sale | AF19: 198044 | AG19: IGST Input Cr : Serv Proc: (1190) Kolkata | AI19: 198044 | AJ19: IGST Input Cr : Serv Proc: (1190) Kolkata | AK19: 0 | AL19: 19 | AM19: H | AN19: A | AP19: 100058228 | AQ19: 43677 | AR19: 43676 | AS19: 0.55850694 | AT19: 0 | AU19: 0 | AX19: 2
A20: 1000 | B20: Tata BlueScope Steel Ltd | C20: 113809 | D20: 95004892 | E20: RV | F20: 1109 | G20: 2019 | H20: 12 | I20: 43901 | J20: 43901 | K20: 302032.8 | L20: =K20-Q20+T20 -> 255960 | M20: INR | N20: 302032.8 | O20: INR | P20: 0 | Q20: 46072.8 | R20: 255960 | S20: 0 | T20: 0 | U20: 312193 | V20: Tata Steel Limited ( Kalinganagar) | Z20: 2525 | AB20: SI1904100059 | AD20: 110000 | AE20: Customer - Domestic | AF20: 501020 | AG20: Revenue DS - Sale of Services Domestic | AI20: 501020 | AJ20: Revenue DS - Sale of Services Domestic | AK20: 0 | AL20: 1 | AM20: S | AR20: 43901 | AS20: 0.70486111 | AT20: 0 | AU20: 0 | AW20: 0 | AX20: 1
A21: 1000 | B21: Tata BlueScope Steel Ltd | C21: 100057906 | E21: AB | F21: 1109 | G21: 2019 | H21: 4 | I21: 43677 | J21: 43677 | K21: -380140.76 | L21: =K21-Q21+T21 -> -380140.76 | M21: INR | N21: -380140.76 | O21: INR | P21: 0 | Q21: 0 | R21: -380140.76 | S21: 0 | T21: 0 | U21: 307259 | V21: Tata Steel Limited | Z21: 100057906 | AD21: 110000 | AE21: Customer - Domestic | AF21: 310300 | AG21: Customer - Advance against Sale | AI21: 310300 | AJ21: Customer - Advance against Sale | AK21: 0 | AL21: 17 | AM21: H | AP21: 100057906 | AQ21: 43677 | AR21: 43677 | AS21: 0.66454861 | AT21: 0 | AU21: 0 | AX21: 1
A22: 1000 | B22: Tata BlueScope Steel Ltd | C22: 1600000147 | D22: TRF ENTRY | E22: DA | F22: 1106 | G22: 2019 | H22: 4 | I22: 43677 | J22: 43677 | K22: 380140.76 | L22: =K22-Q22+T22 -> 380140.76 | M22: INR | N22: 380140.76 | O22: INR | P22: 380140.76 | Q22: 0 | R22: 380140.76 | S22: 0 | T22: 0 | U22: 305576 | V22: Tata Steel Ltd. | X22: Trf to 307259 IL36701907081828 | Y22: Trf entry | Z22: 1600000147 | AD22: 110000 | AE22: Customer - Domestic | AF22: 307259 | AG22: Tata Steel Limited | AI22: 307259 | AJ22: Tata Steel Limited | AK22: 0 | AL22: 4 | AM22: S | AP22: 100057907 | AQ22: 43677 | AR22: 43677 | AS22: 0.6640162 | AT22: 0 | AU22: 0 | AX22: 1
A23: 1000 | B23: Tata BlueScope Steel Ltd | C23: 100078765 | E23: AB | F23: 1101 | G23: 2019 | H23: 5 | I23: 43706 | J23: 43706 | K23: 992081 | L23: =K23-Q23+T23 -> 992081 | M23: INR | N23: 992081 | O23: INR | P23: 0 | Q23: 0 | R23: 992081 | S23: 0 | T23: 0 | U23: 312193 | V23: Tata Steel Limited ( Kalinganagar) | Z23: 100078765 | AD23: 310300 | AE23: Customer - Advance against Sale | AF23: 110000 | AG23: Customer - Domestic | AI23: 110000 | AJ23: Customer - Domestic | AK23: 0 | AL23: 9 | AM23: S | AN23: A | AP23: 100078765 | AQ23: 43706 | AR23: 43706 | AS23: 0.70283565 | AT23: 0 | AU23: 0 | AX23: 10
A24: 1000 | B24: Tata BlueScope Steel Ltd | C24: 100081970 | E24: AB | F24: 1109 | G24: 2019 | H24: 5 | I24: 43708 | J24: 43708 | K24: -254204.56 | L24: =K24-Q24+T24 -> -254204.56 | M24: INR | N24: -254204.56 | O24: INR | P24: 0 | Q24: 0 | R24: -254204.56 | S24: 0 | T24: 0 | U24: 307259 | V24: Tata Steel Limited | Z24: 100081970 | AD24: 110000 | AE24: Customer - Domestic | AF24: 310300 | AG24: Customer - Advance against Sale | AI24: 310300 | AJ24: Customer - Advance against Sale | AK24: 0 | AL24: 17 | AM24: H | AP24: 100081970 | AQ24: 43708 | AR24: 43710 | AS24: 0.28239583 | AT24: 0 | AU24: 0 | AX24: 1
A25: 1000 | B25: Tata BlueScope Steel Ltd | C25: 100082479 | E25: AB | F25: 1101 | G25: 2019 | H25: 5 | I25: 43708 | J25: 43708 | K25: -365469.45 | L25: =K25-Q25+T25 -> -365469.45 | M25: INR | N25: -365469.45 | O25: INR | P25: 0 | Q25: 0 | R25: -365469.45 | S25: 0 | T25: 0 | U25: 318999 | V25: Tata Steel Limited | Z25: 100082479 | AD25: 111105 | AE25: Customer - Retention | AF25: 110000 | AG25: Customer - Domestic | AI25: 110000 | AJ25: Customer - Domestic | AK25: 0 | AL25: 19 | AM25: H | AN25: Y | AP25: 100082479 | AQ25: 43708 | AR25: 43711 | AS25: 0.23831019 | AT25: 0 | AU25: 0 | AX25: 4
A26: 1000 | B26: Tata BlueScope Steel Ltd | C26: 100058249 | E26: AB | F26: 1109 | G26: 2019 | H26: 4 | I26: 43677 | J26: 43677 | K26: -3614555.8 | L26: =K26-Q26+T26 -> -3614555.8 | M26: INR | N26: -3614555.8 | O26: INR | P26: 0 | Q26: 0 | R26: -3614555.8 | S26: 0 | T26: 0 | U26: 318179 | V26: Tata Steel Limited | Z26: 100058249 | AD26: 110000 | AE26: Customer - Domestic | AF26: 110000 | AG26: Customer - Domestic | AI26: 110000 | AJ26: Customer - Domestic | AK26: 0 | AL26: 17 | AM26: H | AP26: 100058249 | AQ26: 43677 | AR26: 43678 | AS26: 0.22288194 | AT26: 0 | AU26: 0 | AX26: 3
A27: 1000 | B27: Tata BlueScope Steel Ltd | C27: 100082479 | E27: AB | F27: 1101 | G27: 2019 | H27: 5 | I27: 43708 | J27: 43708 | K27: 509193.39 | L27: =K27-Q27+T27 -> 509193.39 | M27: INR | N27: 509193.39 | O27: INR | P27: 509193.39 | Q27: 0 | R27: 509193.39 | S27: 0 | T27: 0 | U27: 318999 | V27: Tata Steel Limited | X27: Retention Erection | Z27: 100082479 | AD27: 111105 | AE27: Customer - Retention | AF27: 110000 | AG27: Customer - Domestic | AI27: 110000 | AJ27: Customer - Domestic | AK27: 0 | AL27: 9 | AM27: S | AN27: Y | AP27: 100173604 | AQ27: 43799 | AR27: 43711 | AS27: 0.23831019 | AT27: 0 | AU27: 0 | AX27: 2
A28: 1000 | B28: Tata BlueScope Steel Ltd | C28: 1400003592 | E28: DZ | F28: 1106 | G28: 2019 | H28: 4 | I28: 43650 | J28: 43650 | K28: -3143638 | L28: =K28-Q28+T28 -> -3143638 | M28: INR | N28: -3143638 | O28: INR | P28: 0 | Q28: 0 | R28: -3143638 | S28: 0 | T28: 0 | U28: 305576 | V28: Tata Steel Ltd. | X28: IL36701907045618|HDFCR52019070 | Y28: IL36701907045618|HDFCR520 | Z28: 1400003592 | AC28: Receipt | AD28: 310300 | AE28: Customer - Advance against Sale | AF28: 101105 | AG28: Stanchart- Clearing Pune | AI28: 101105 | AJ28: Stanchart- Clearing Pune | AK28: 0 | AL28: 19 | AM28: H | AN28: A | AP28: 100055938 | AQ28: 43671 | AR28: 43651 | AS28: 0.75216435 | AT28: 0 | AU28: 0 | AX28: 2
A29: 1000 | B29: Tata BlueScope Steel Ltd | C29: 100075998 | E29: AB | F29: 1106 | G29: 2019 | H29: 5 | I29: 43703 | J29: 43703 | K29: 6259900 | L29: =K29-Q29+T29 -> 6259900 | M29: INR | N29: 6259900 | O29: INR | P29: 0 | Q29: 0 | R29: 6259900 | S29: 0 | T29: 0 | U29: 309728 | V29: Tata Steel Ltd - Growth Shop | Z29: 100075998 | AD29: 310300 | AE29: Customer - Advance against Sale | AF29: 110000 | AG29: Customer - Domestic | AI29: 110000 | AJ29: Customer - Domestic | AK29: 0 | AL29: 9 | AM29: S | AN29: A | AP29: 100075998 | AQ29: 43703 | AR29: 43703 | AS29: 0.73967593 | AT29: 0 | AU29: 0 | AX29: 2
A30: 1000 | B30: Tata BlueScope Steel Ltd | C30: 1600000180 | D30: TRF ENTRY | E30: DA | F30: 1106 | G30: 2019 | H30: 5 | I30: 43706 | J30: 43706 | K30: -303810.6 | L30: =K30-Q30+T30 -> -303810.6 | M30: INR | N30: -303810.6 | O30: INR | P30: -303810.6 | Q30: 0 | R30: -303810.6 | S30: 0 | T30: 0 | U30: 312193 | V30: Tata Steel Limited ( Kalinganagar) | X30: Trf Fm 309085 | Y30: Trf Entry | Z30: 1600000180 | AD30: 310300 | AE30: Customer - Advance against Sale | AF30: 309085 | AG30: TATA STEEL LIMITED | AI30: 309085 | AJ30: TATA STEEL LIMITED | AK30: 0 | AL30: 19 | AM30: H | AN30: A | AP30: 100078765 | AQ30: 43706 | AR30: 43706 | AS30: 0.46318287 | AT30: 0 | AU30: 0 | AX30: 2
A31: 1000 | B31: Tata BlueScope Steel Ltd | C31: 101042 | D31: SI1904100006 | E31: RV | F31: 1109 | G31: 2019 | H31: 1 | I31: 43584 | J31: 43584 | K31: 212211.2 | L31: =K31-Q31+T31 -> 179840 | M31: INR | N31: 212211.2 | O31: INR | P31: 0 | Q31: 32371.2 | R31: 179840 | S31: 0 | T31: 0 | U31: 312193 | V31: Tata Steel Limited ( Kalinganagar) | Z31: 2316 | AB31: 4700069343/172 | AD31: 110000 | AE31: Customer - Domestic | AF31: 501020 | AG31: Revenue DS - Sale of Services Domestic | AI31: 501020 | AJ31: Revenue DS - Sale of Services Domestic | AK31: 0 | AL31: 1 | AM31: S | AP31: 100005107 | AQ31: 43585 | AR31: 43584 | AS31: 0.60512731 | AT31: 0 | AU31: 0 | AX31: 1
A32: 1000 | B32: Tata BlueScope Steel Ltd | C32: 100116355 | E32: AB | F32: 1109 | G32: 2019 | H32: 6 | I32: 43738 | J32: 43738 | K32: 308876.8 | L32: =K32-Q32+T32 -> 308876.8 | M32: INR | N32: 308876.8 | O32: INR | P32: 0 | Q32: 0 | R32: 308876.8 | S32: 0 | T32: 0 | U32: 312193 | V32: Tata Steel Limited ( Kalinganagar) | X32: SI1904100034 | Z32: 2316 | AB32: 4700069343/172 | AD32: 110000 | AE32: Customer - Domestic | AF32: 110000 | AG32: Customer - Domestic | AI32: 110000 | AJ32: Customer - Domestic | AK32: 0 | AL32: 4 | AM32: S | AP32: 100123318 | AQ32: 43738 | AR32: 43738 | AS32: 0.22452546 | AT32: 0 | AU32: 0 | AX32: 2
A33: 1000 | B33: Tata BlueScope Steel Ltd | C33: 100081967 | E33: AB | F33: 1109 | G33: 2019 | H33: 5 | I33: 43708 | J33: 43708 | K33: 1833661 | L33: =K33-Q33+T33 -> 1833661 | M33: INR | N33: 1833661 | O33: INR | P33: 0 | Q33: 0 | R33: 1833661 | S33: 0 | T33: 0 | U33: 305576 | V33: Tata Steel Ltd. | X33: CI1904103045 | Z33: 60427 | AB33: 4404899885/901 | AD33: 110000 | AE33: Customer - Domestic | AF33: 110000 | AG33: Customer - Domestic | AI33: 110000 | AJ33: Customer - Domestic | AK33: 0 | AL33: 4 | AM33: S | AP33: 100122444 | AQ33: 43738 | AR33: 43710 | AS33: 0.27603009 | AT33: 0 | AU33: 0 | AX33: 2
A34: 1000 | B34: Tata BlueScope Steel Ltd | C34: 100113124 | D34: R OFF | E34: SA | F34: 1108 | G34: 2019 | H34: 6 | I34: 43732 | J34: 43732 | K34: -0.43 | L34: =K34-Q34+T34 -> -0.43 | M34: INR | N34: -0.43 | O34: INR | P34: 0 | Q34: 0 | R34: -0.43 | S34: 0 | T34: 0 | U34: 306263 | V34: Tata Steel limited ( CRC ) | X34: R off-Small Balance306263 | Y34: R off | Z34: 100113124 | AD34: 110000 | AE34: Customer - Domestic | AF34: 891305 | AG34: Rounding differences | AI34: 891305 | AJ34: Rounding differences | AK34: 0 | AL34: 17 | AM34: H | AP34: 100113124 | AQ34: 43732 | AR34: 43733 | AS34: 0.69230324 | AT34: 0 | AU34: 0 | AX34: 2
A35: 1000 | B35: Tata BlueScope Steel Ltd | C35: 101052 | D35: SI1904100007 | E35: RV | F35: 1109 | G35: 2019 | H35: 1 | I35: 43584 | J35: 43584 | K35: 309431.4 | L35: =K35-Q35+T35 -> 262230 | M35: INR | N35: 309431.4 | O35: INR | P35: 0 | Q35: 47201.4 | R35: 262230 | S35: 0 | T35: 0 | U35: 312193 | V35: Tata Steel Limited ( Kalinganagar) | Z35: 2316 | AB35: 4700069343/172 | AD35: 110000 | AE35: Customer - Domestic | AF35: 501020 | AG35: Revenue DS - Sale of Services Domestic | AI35: 501020 | AJ35: Revenue DS - Sale of Services Domestic | AK35: 0 | AL35: 1 | AM35: S | AP35: 100005107 | AQ35: 43585 | AR35: 43584 | AS35: 0.69956019 | AT35: 0 | AU35: 0 | AX35: 1
A36: 1000 | B36: Tata BlueScope Steel Ltd | C36: 1400004796 | E36: DZ | F36: 1101 | G36: 2019 | H36: 5 | I36: 43682 | J36: 43682 | K36: -1743896 | L36: =K36-Q36+T36 -> -1743896 | M36: INR | N36: -1743896 | O36: INR | P36: 0 | Q36: 0 | R36: -1743896 | S36: 0 | T36: 0 | U36: 318999 | V36: Tata Steel Limited | X36: IL36701908052447|HDFCR52019080 | Y36: IL36701908052447|HDFCR520 | Z36: 1400004796 | AC36: Receipt | AD36: 310300 | AE36: Customer - Advance against Sale | AF36: 101105 | AG36: Stanchart- Clearing Pune | AI36: 101105 | AJ36: Stanchart- Clearing Pune | AK36: 0 | AL36: 19 | AM36: H | AN36: A | AP36: 100076146 | AQ36: 43703 | AR36: 43685 | AS36: 0.48803241 | AT36: 0 | AU36: 0 | AX36: 2
A37: 1000 | B37: Tata BlueScope Steel Ltd | C37: 1400005437 | E37: DZ | F37: 1101 | G37: 2019 | H37: 5 | I37: 43706 | J37: 43706 | K37: -3431713.4 | L37: =K37-Q37+T37 -> -3431713.4 | M37: INR | N37: -3431713.4 | O37: INR | P37: 0 | Q37: 0 | R37: -3431713.4 | S37: 0 | T37: 0 | U37: 312948 | V37: Tata Steel Limited, �Wire Division | X37: IL36701908294865|HDFCR52019082 | Y37: IL36701908294865|HDFCR520 | Z37: 1400005437 | AC37: Receipt | AD37: 310300 | AE37: Customer - Advance against Sale | AF37: 101105 | AG37: Stanchart- Clearing Pune | AI37: 101105 | AJ37: Stanchart- Clearing Pune | AK37: 0 | AL37: 19 | AM37: H | AN37: A | AP37: 100081995 | AQ37: 43708 | AR37: 43707 | AS37: 0.49556713 | AT37: 0 | AU37: 0 | AX37: 2
A38: 1000 | B38: Tata BlueScope Steel Ltd | C38: 100058463 | E38: AB | F38: 1109 | G38: 2019 | H38: 4 | I38: 43677 | J38: 43677 | K38: 6579 | L38: =K38-Q38+T38 -> 6579 | M38: INR | N38: 6579 | O38: INR | P38: 0 | Q38: 0 | R38: 6579 | S38: 0 | T38: 0 | U38: 312193 | V38: Tata Steel Limited ( Kalinganagar) | X38: TDS SI1904100022 | Z38: 2316 | AB38: 4700069343/172 | AD38: 110000 | AE38: Customer - Domestic | AF38: 110000 | AG38: Customer - Domestic | AI38: 110000 | AJ38: Customer - Domestic | AK38: 0 | AL38: 4 | AM38: S | AP38: 100173563 | AQ38: 43799 | AR38: 43678 | AS38: 0.57675926 | AT38: 0 | AU38: 0 | AX38: 4
A39: 1000 | B39: Tata BlueScope Steel Ltd | C39: 100055956 | E39: AB | F39: 1109 | G39: 2019 | H39: 4 | I39: 43671 | J39: 43671 | K39: -672600 | L39: =K39-Q39+T39 -> -672600 | M39: INR | N39: -672600 | O39: INR | P39: 0 | Q39: 0 | R39: -672600 | S39: 0 | T39: 0 | U39: 313029 | V39: Tata Steel Limited | Z39: 100055956 | AD39: 110000 | AE39: Customer - Domestic | AF39: 310300 | AG39: Customer - Advance against Sale | AI39: 310300 | AJ39: Customer - Advance against Sale | AK39: 0 | AL39: 17 | AM39: H | AP39: 100055956 | AQ39: 43671 | AR39: 43671 | AS39: 0.65671296 | AT39: 0 | AU39: 0 | AX39: 1
